Workbook
Name Kesko_2012: 'SVAR TILL UPPGIFTER'!$A$70

Sheet SVAR TILL UPPGIFTER
A1: USER INPUT | E1: Bygg en excel-modell för beräkning av det teoretiska terminspriset.
B2: Datum | C2: Vilken termin? | E2: =100%-(((1 + H10 * (G10/360)) / (1 + E10 * (D10/360))) - 1) * (360/I10) -> 0.99491115
B3: 41710 | C3: Juni
B9: Utgångsdag 1 | C9: Prisnotering | D9: D1 | E9: R1 | F9: Utgångdag 2 | G9: D2 | H9: R2 | I9: Dterm
B10: =_xlfn.XLOOKUP(C3,Räteterminer!$B$1:$E$1,Räteterminer!$B$2:$E$2) -> 41805 | C10: =_xlfn.XLOOKUP(C3,Räteterminer!$B$1:$E$1,Räteterminer!$B$3:$E$3) -> 0.00295 | D10: =B10-B3 -> 95 | E10: =_xlfn.XLOOKUP(D10, Euribor_360!$A$3:$H$3, Euribor_360!$A$2:$H$2, "not found", -1) -> 0.00304 | F10: =_xlfn.MINIFS(Räteterminer!$B$2:$E$2, Räteterminer!$B$2:$E$2, ">" & B10) -> 41897 | G10: =F10-B3 -> 187 | H10: =_xlfn.XLOOKUP(G10, Euribor_360!$A$3:$H$3, Euribor_360!$A$2:$H$2, "not found", -1) -> 0.00405 | I10: =G10-D10 -> 92
A14: Utnyttja din modell och räkna ut de teoretiska priserna den 12.3.2014 för ränteterminer som utgick i juni, september och december.
A16: TERMIN | B16: Utgångsdag 1 | C16: Prisnotering | D16: D1 | E16: R1 | F16: Utgångdag 2 | G16: D2 | H16: R2 | I16: Dterm | J16: Teoretiska pris | K16: Marknads notering | L16: Skillnad
A17: Juni | B17: =_xlfn.XLOOKUP(A17,Räteterminer!$B$1:$E$1,Räteterminer!$B$2:$E$2) -> 41805 | C17: =_xlfn.XLOOKUP(A17,Räteterminer!$B$1:$E$1,Räteterminer!$B$3:$E$3) -> 0.00295 | D17: =B17-$B$3 -> 95 | E17: =_xlfn.XLOOKUP(D17, Euribor_360!$A$3:$H$3, Euribor_360!$A$2:$H$2, "not found", -1) -> 0.00304 | F17: =_xlfn.MINIFS(Räteterminer!$B$2:$E$2, Räteterminer!$B$2:$E$2, ">" & B17) -> 41897 | G17: =F17-$B$3 -> 187 | H17: =_xlfn.XLOOKUP(G17, Euribor_360!$A$3:$H$3, Euribor_360!$A$2:$H$2, "not found", -1) -> 0.00405 | I17: =G17-D17 -> 92 | J17: =100%-(((1 + H17 * (G17/360)) / (1 + E17 * (D17/360))) - 1) * (360/I17) -> 0.99491115 | K17: =100%-C17 -> 0.99705 | L17: =ABS(K17-J17) -> 0.0021388524
A18: TERMIN | B18: Utgångsdag 1 | C18: Prisnotering | D18: D1 | E18: R1 | F18: Utgångdag 2 | G18: D2 | H18: R2 | I18: Dterm | J18: Teoretiska pris | K18: Marknads notering | L18: Skillnad
A19: September | B19: =_xlfn.XLOOKUP(A19,Räteterminer!$B$1:$E$1,Räteterminer!$B$2:$E$2) -> 41897 | C19: =_xlfn.XLOOKUP(A19,Räteterminer!$B$1:$E$1,Räteterminer!$B$3:$E$3) -> 0.00295 | D19: =B19-$B$3 -> 187 | E19: =_xlfn.XLOOKUP(D19, Euribor_360!$A$3:$H$3, Euribor_360!$A$2:$H$2, "not found", -1) -> 0.00405 | F19: =_xlfn.MINIFS(Räteterminer!$B$2:$E$2, Räteterminer!$B$2:$E$2, ">" & B19) -> 41988 | G19: =F19-$B$3 -> 278 | H19: =_xlfn.XLOOKUP(G19, Euribor_360!$A$3:$H$3, Euribor_360!$A$2:$H$2, "not found", -1) -> 0.0049 | I19: =G19-D19 -> 91 | J19: =100%-(((1 + H19 * (G19/360)) / (1 + E19 * (D19/360))) - 1) * (360/I19) -> 0.99336725 | K19: =100%-C19 -> 0.99705 | L19: =ABS(K19-J19) -> 0.0036827496
A20: TERMIN | B20: Utgångsdag 1 | C20: Prisnotering | D20: D1 | E20: R1 | F20: Utgångdag 2 | G20: D2 | H20: R2 | I20: Dterm | J20: Teoretiska pris | K20: Marknads notering | L20: Skillnad
A21: December | B21: =_xlfn.XLOOKUP(A21,Räteterminer!$B$1:$E$1,Räteterminer!$B$2:$E$2) -> 41988 | C21: =_xlfn.XLOOKUP(A21,Räteterminer!$B$1:$E$1,Räteterminer!$B$3:$E$3) -> 0.0031 | D21: =B21-$B$3 -> 278 | E21: =_xlfn.XLOOKUP(D21, Euribor_360!$A$3:$H$3, Euribor_360!$A$2:$H$2, "not found", -1) -> 0.0049 | F21: =_xlfn.MINIFS(Räteterminer!$B$2:$E$2, Räteterminer!$B$2:$E$2, ">" & B21) -> 42079 | G21: =F21-$B$3 -> 369 | H21: =_xlfn.XLOOKUP(G21, Euribor_360!$A$3:$H$3, Euribor_360!$A$2:$H$2, "not found", -1) -> 0.00574 | I21: =G21-D21 -> 91 | J21: =100%-(((1 + H21 * (G21/360)) / (1 + E21 * (D21/360))) - 1) * (360/I21) -> 0.99172516 | K21: =100%-C21 -> 0.9969 | L21: =ABS(K21-J21) -> 0.0051748428
A22: Hur bra motsvarade marknadsnoteringar och de teoretiska priserna varandra?
A23: De teoretiska priserna och markandsnoterningarna motsvarade varandra mycket dåligt.
A27: Datum | B27: Utnyttja din modell och räkna ut de teoretiska priserna den 11.4.2014 för juni- september- och decemberterminerna.
A28: 41740
A29: TERMIN | B29: Utgångsdag 1 | C29: Prisnotering | D29: D1 | E29: R1 | F29: Utgångdag 2 | G29: D2 | H29: R2 | I29: Dterm | J29: Teoretiska pris | K29: Marknads notering | L29: Skillnad
A30: Juni | B30: =_xlfn.XLOOKUP(A30,Räteterminer!$B$1:$E$1,Räteterminer!$B$2:$E$2) -> 41805 | C30: =_xlfn.XLOOKUP(A30,Räteterminer!$B$1:$E$1,Räteterminer!$B$3:$E$3) -> 0.00295 | D30: =B30-A28 -> 65 | E30: =_xlfn.XLOOKUP(D30, euribor_11_4!$A$3:$H$3, euribor_11_4!$A$2:$H$2, "not found", -1) -> 0.0029 | F30: =_xlfn.MINIFS(Räteterminer!$B$2:$E$2, Räteterminer!$B$2:$E$2, ">" & B30) -> 41897 | G30: =F30-A28 -> 157 | H30: =_xlfn.XLOOKUP(G30, euribor_11_4!$A$3:$H$3, euribor_11_4!$A$2:$H$2, "not found", -1) -> 0.00328 | I30: =G30-D30 -> 92 | J30: =100%-(((1 + H30 * (G30/360)) / (1 + E30 * (D30/360))) - 1) * (360/I30) -> 0.99645338 | K30: =100%-C30 -> 0.99705 | L30: =ABS(K30-J30) -> 0.00059662121
A31: TERMIN | B31: Utgångsdag 1 | C31: Prisnotering | D31: D1 | E31: R1 | F31: Utgångdag 2 | G31: D3 | H31: R2 | I31: Dterm | J31: Teoretiska pris | K31: Marknads notering | L31: Skillnad
A32: September | B32: =_xlfn.XLOOKUP(A32,Räteterminer!$B$1:$E$1,Räteterminer!$B$2:$E$2) -> 41897 | C32: =_xlfn.XLOOKUP(A32,Räteterminer!$B$1:$E$1,Räteterminer!$B$3:$E$3) -> 0.00295 | D32: =B32-A28 -> 157 | E32: =_xlfn.XLOOKUP(D32, euribor_11_4!$A$3:$H$3, euribor_11_4!$A$2:$H$2, "not found", -1) -> 0.00328 | F32: =_xlfn.MINIFS(Räteterminer!$B$2:$E$2, Räteterminer!$B$2:$E$2, ">" & B32) -> 41988 | G32: =F32-A28 -> 248 | H32: =_xlfn.XLOOKUP(G32, euribor_11_4!$A$3:$H$3, euribor_11_4!$A$2:$H$2, "not found", -1) -> 0.00428 | I32: =G32-D32 -> 91 | J32: =100%-(((1 + H32 * (G32/360)) / (1 + E32 * (D32/360))) - 1) * (360/I32) -> 0.9940033 | K32: =100%-C32 -> 0.99705 | L32: =ABS(K32-J32) -> 0.0030466968
A33: TERMIN | B33: Utgångsdag 1 | C33: Prisnotering | D33: D1 | E33: R1 | F33: Utgångdag 2 | G33: D4 | H33: R2 | I33: Dterm | J33: Teoretiska pris | K33: Marknads notering | L33: Skillnad
A34: December | B34: =_xlfn.XLOOKUP(A34,Räteterminer!$B$1:$E$1,Räteterminer!$B$2:$E$2) -> 41988 | C34: =_xlfn.XLOOKUP(A34,Räteterminer!$B$1:$E$1,Räteterminer!$B$3:$E$3) -> 0.0031 | D34: =B34-A28 -> 248 | E34: =_xlfn.XLOOKUP(D34, euribor_11_4!$A$3:$H$3, euribor_11_4!$A$2:$H$2, "not found", -1) -> 0.00428 | F34: =_xlfn.MINIFS(Räteterminer!$B$2:$E$2, Räteterminer!$B$2:$E$2, ">" & B34) -> 42079 | G34: =F34-A28 -> 339 | H34: =_xlfn.XLOOKUP(G34, euribor_11_4!$A$3:$H$3,euribor_11_4!$A$2:$H$2, "not found", -1) -> 0.00511 | I34: =G34-D34 -> 91 | J34: =100%-(((1 + H34 * (G34/360)) / (1 + E34 * (D34/360))) - 1) * (360/I34) -> 0.99264969 | K34: =100%-C34 -> 0.9969 | L34: =ABS(K34-J34) -> 0.0042503061
A37: Lånebelopp | B37: Beräkna de totala kostnaderna för kombinationen lånet + terminskontrakt för fem olika möjliga räntenivåer i september (inklusive den teoretiska räntan som du räknade ut i punkt A) och presentera resultaten av din analys i tabellform. Presentera dina resultat även i grafisk form.
A38: 2000000
A39: Ränte-% | C39: Räntekostnader för lånet | E39: Nettovärdet av terminskontrakt vid terminens utgång i september | G39: Prolongerat nettovärde av terminskontrakt i december | I39: Totala kostnader (Låneränta och termin)
A40: 0.003 | C40: =$A$38*A40*($I$19/360) -> 1516.6667 | E40: =($A$38*(A40-$A$42)*($I$19/360))/(1+A40*($I$19/360)) -> -1835.1651 | G40: =E40*(1+A40*($I$19/360)) -> -1836.5568 | I40: =C40-G40 -> 3353.2234
A41: 0.005 | C41: =$A$38*A41*($I$19/360) -> 2527.7778 | E41: =($A$38*(A41-$A$42)*($I$19/360))/(1+A41*($I$19/360)) -> -824.4037 | G41: =E41*(1+A41*($I$19/360)) -> -825.44566 | I41: =C41-G41 -> 3353.2234 | T41: #VALUE!
A42: =100%-J19 -> 0.0066327496 | C42: =$A$38*A42*($I$19/360) -> 3353.2234 | E42: =($A$38*(A42-$A$42)*($I$19/360))/(1+A42*($I$19/360)) -> 0 | G42: =E42*(1+A42*($I$19/360)) -> 0 | I42: =C42-G42 -> 3353.2234
A43: 0.01 | C43: =$A$38*A43*($I$19/360) -> 5055.5556 | E43: =($A$38*(A43-$A$42)*($I$19/360))/(1+A43*($I$19/360)) -> 1698.0399 | G43: =E43*(1+A43*($I$19/360)) -> 1702.3321 | I43: =C43-G43 -> 3353.2234
A44: 0.012 | C44: =$A$38*A44*($I$19/360) -> 6066.6667 | E44: =($A$38*(A44-$A$42)*($I$19/360))/(1+A44*($I$19/360)) -> 2705.2373 | G44: =E44*(1+A44*($I$19/360)) -> 2713.4432 | I44: =C44-G44 -> 3353.2234
A65: C. Användning av räntederivat i finska företag Försök hitta tre finska företag som har utnyttjat ränteterminer, räntefuturer och/eller ränteswappar och berätta kort hur företagen har tagit upp informationen om dessa räntederivat i sina bokslut. (Tips! Googla med "korkojohdannai" för att hitta bokslut som innehåller olika räntederivat).
A69: Kesko | C69: Kesko använder räntederivat för att reglera låneportföljens räntebindningstid (målduration 3 år) och värderar öppna avtal till verkligt värde i bokslutet. I bokföringen tillämpas försiktighetsprincipen, vilket innebär att orealiserade värdeminskningar bokförs som kostnad, medan orealiserade värdeökningar inte intäktsförs. (Sida 130)
A70: Link_Kesko_2012
A73: Beräkna de teoretiska priserna den 10.4.2019 för Hennes & Mauritz aktieterminer som utgick i april och i juni 2019.
A75: Datum | B75: Börskurs per 30 november | C75: Utbetalning1 | D75: Avstämningsdag1 | E75: Utbetalning2 | F75: avstämningsdag2 | G75: april(3fredagen i månad) | H75: Juni | I75: t1 | J75: t2 | K75: Euribor 1v | L75: Euribor 3mån
A76: 43565 | B76: 167.64 | C76: 4.9 | D76: 43594 | E76: 4.85 | F76: 43781 | G76: 43572 | H76: 43636 | I76: =G76-A76 -> 7 | J76: =H76-A76 -> 71 | K76: -0.00378 | L76: -0.0031
A77: April-termin | B77: =B76*(1+(K76*(I76/360))) -> 167.62768 | C77: Juni-Termin | D77: =B76*(1+(L76*(J76/360)))-C76 -> 162.63751
F78: Vad berättar marknadspriset om förväntningarna på marknaden?
B79: Termin | C79: Teoretisktpris | D79: Marknadspris (sälj) | E79: Skillnad
B80: April | C80: =B77 -> 167.62768 | D80: 163.85 | E80: =C80-D80 -> 3.7776785 | F80: Marknadspriset ligger about 4 kronor under det teoretiska priset för båda terminerna. Det betyder att marknaden den 10 april var bearish och investerare förväntar sig att H&M aktien ska falla i värde.
...

Sheet Euribor_360
A1: 1vecka | B1: 2veckor | C1: 1mån | D1: 2mån | E1: 3mån | F1: 6mån | G1: 9mån | H1: 12mån
A2: 0.00195 | B2: 0.00208 | C2: 0.00233 | D2: 0.00268 | E2: 0.00304 | F2: 0.00405 | G2: 0.0049 | H2: 0.00574
A3: 7 | B3: 14 | C3: 30 | D3: 60 | E3: 90 | F3: 180 | G3: 270 | H3: 360

Sheet Räteterminer
A1: Termin | B1: Juni | C1: September | D1: December | E1: Mars
A2: Utgångsdag | B2: 41805 | C2: 41897 | D2: 41988 | E2: 42079
A3: Prisnotering | B3: 0.00295 | C3: 0.00295 | D3: 0.0031 | E3: 0.00325

Sheet Eurex_11_4
B1: Lastprice
A2: 41791 | B2: 99.71
A3: 41883 | B3: 99.74
A4: 41974 | B4: 99.735
A5: 42064 | B5: 99.72

Sheet euribor_11_4
A1: 1vecka | B1: 2veckor | C1: 1mån | D1: 2mån | E1: 3mån | F1: 6mån | G1: 9mån | H1: 12mån
A2: 0.00223 | B2: 0.00231 | C2: 0.00253 | D2: 0.0029 | E2: 0.00328 | F2: 0.00428 | G2: 0.00511 | H2: 0.00601
A3: 7 | B3: 14 | C3: 30 | D3: 60 | E3: 90 | F3: 180 | G3: 270 | H3: 360

Sheet euribor_10_4_19
A1: 1v | B1: 1mån | C1: 3mån | D1: 6mån | E1: 12mån
A2: -0.00378 | B2: -0.00367 | C2: -0.0031 | D2: -0.00231 | E2: -0.00112
